# Explanation
### GPT-3.5

<details>
  <summary><span style="font-size:20px;font-weight:gold;">Explanation 1 (10 lines, 3 code blocks)</span></summary>
  
  Title: Diagnosis of test `test_rename_with_custom_indexer`
Details: The test `test_rename_with_custom_indexer` is testing the `rename` method of the `Series` class in the `pandas.core.series` package. The test creates an instance of `Series` with values `[1, 2, 3]` and attempts to rename it using a custom indexer `MyIndexer`. However, the test fails with a `TypeError` indicating that the `MyIndexer` object is not iterable.

Looking at the code of the `Series.rename` method, we can see that it accepts an `index` parameter which can be a scalar, hashable sequence, dict-like, or function. In the test, an instance of `MyIndexer` is passed as the `index` argument. However, `MyIndexer` is not iterable, which results in the `TypeError` when trying to iterate over it.

To fix this issue, we need to ensure that the `index` argument passed to the `Series.rename` method is iterable. This can be done by either passing a valid iterable object such as a list or tuple, or by modifying the `MyIndexer` class to implement the necessary iterable interface.

Suggested fix:
- Modify the `test_rename_with_custom_indexer` test to pass a valid iterable object as the `index` argument.
- Update the `MyIndexer` class to implement the necessary iterable interface if it needs to be used as the `index` argument.

Code snippet of the failing test:
```python
    def test_rename_with_custom_indexer(self):
        # GH 27814
        class MyIndexer:
            pass

        ix = MyIndexer()
        s = Series([1, 2, 3]).rename(ix)
```

Suggested fix:
```python
    def test_rename_with_custom_indexer(self):
        # GH 27814
        ix = [1, 2, 3]
        s = Series([1, 2, 3]).rename(ix)
```
or
```python
    class MyIndexer:
        def __iter__(self):
            # implement the iterable interface
            yield 1
            yield 2
            yield 3

    ix = MyIndexer()
    s = Series([1, 2, 3]).rename(ix)
```
</details>
<hr>


<details>
  <summary><span style="font-size:20px;font-weight:gold;">Explanation 2 (17 lines, 3 code blocks)</span></summary>
  
  The test `test_rename_with_custom_indexer_inplace` is calling the `rename` method of the `Series` class in the pandas core module. Here is the snippet of the `rename` method:

```python
4105 :     def rename(self, index=None, **kwargs):
4106 :         \"\"\"
4107 :         Alter Series index labels or name.
...
4171 :         if non_mapping:
4172 :             return self._set_name(index, inplace=kwargs.get(\"inplace\"))
4173 :         return super().rename(index=index, **kwargs)
```

Based on the error message and call stack, the error occurred at line 286 of the test, where `s.rename(ix, inplace=True)` is called. The error message indicates that a `TypeError` occurred during the execution of the `rename` method. It specifically states that the `'MyIndexer' object is not iterable`. 

To understand how this error occurred, we need to examine the `rename` method. The method checks whether the `index` parameter passed to it is a scalar or a non-mapping object (such as a list-like object that is not dict-like). If the `index` is a scalar or a non-mapping object, it calls the `_set_name` method with the `index` parameter and the `inplace` parameter passed to the `rename` method. Otherwise, it calls the `rename` method of the super class.

Since the error message mentions that the `'MyIndexer' object is not iterable`, it implies that the `index` parameter supplied to the `rename` method is not a scalar or a non-mapping object. This indicates that the `ix` object of the `MyIndexer` class is causing the error. The `MyIndexer` class is defined within the `test_rename_with_custom_indexer_inplace` test method.

To resolve this error, the `MyIndexer` class should either implement the required methods to be considered a valid indexer for the `rename` method, or a valid index-like object should be used as the `index` parameter when calling the `rename` method.

To fix the issue, you can modify the test to use a valid index-like object instead of the `MyIndexer` class, or modify the `MyIndexer` class to provide the required methods for it to be considered a valid indexer by the `rename` method.

Here is the suggested fix:

```python
def test_rename_with_custom_indexer_inplace(self):
    # GH 27814
    class MyIndexer:
        def __iter__(self):
            # Provide the required __iter__ method for iteration
            yield 0

    ix = MyIndexer()
    s = Series([1, 2, 3])
    s.rename(ix, inplace=True)
```

This modified `MyIndexer` class includes the `__iter__` method, which allows it to be considered an iterable object.

Alternatively, you can use a valid index-like object instead of the `MyIndexer` class:

```python
def test_rename_with_custom_indexer_inplace(self):
    # GH 27814
    ix = pd.Index([0])
    s = Series([1, 2, 3])
    s.rename(ix, inplace=True)
```

In this case, the `pd.Index` class is used to create a valid index-like object.

Note: The exact fix depends on the requirements and intentions of the test code.

Suggested fix:

pandas.core.series.Series.rename(Any, inplace=bool)
Title: Diagnosis of test `test_rename_with_custom_indexer_inplace`
Details: The test `test_rename_with_custom_indexer_inplace` is failing with a `TypeError` indicating that the `'MyIndexer' object is not iterable`. The error occurs at line 286 of the test, where the `rename` method of the `Series` class is called. The `rename` method checks whether the `index` parameter is a scalar or a non-mapping object. If it is, it calls the `_set_name` method with the `index` parameter. Otherwise, it calls the `rename` method of the super class. Since the error message points to the `'MyIndexer' object is not iterable`, it suggests that the `MyIndexer` class used as the `index` parameter is causing the error. To fix this, the `MyIndexer` class should implement the required methods to be considered a valid indexer for the `rename` method, or a valid index-like object should be used instead.

Suggested fix:
pandas.core.series.Series.rename(Any, inplace=bool)
</details>
<hr>


<details>
  <summary><span style="font-size:20px;font-weight:gold;">Explanation 3 (4 lines, 0 code blocks)</span></summary>
  
  The failing test `['pandas.tests.series.test_alter_axes.TestSeriesAlterAxes.test_rename_with_custom_indexer()']` covers classes from various packages in the pandas library, including `pandas.core.series`, `pandas.core.generic`, `pandas.core.indexes.base`, and `pandas.core.common`.
The test `test_rename_with_custom_indexer` failed with a `TypeError` when calling the `rename()` method on a `Series` object. The error message indicates that the `'MyIndexer'` object is not iterable.

Based on the given code snippet, the `rename()` method is called on a `Series` object with the argument `ix`, which is an instance of the `MyIndexer` class. The error occurs when the method tries to convert the `ix` argument to a list using the `list()` function. This conversion fails because the `MyIndexer` class does not implement the iterable protocol.

To further investigate the issue, let's retrieve the code snippet for the `rename()` method in the `Series` class.
</details>
<hr>


<details>
  <summary><span style="font-size:20px;font-weight:gold;">Explanation 4 (18 lines, 0 code blocks)</span></summary>
  
  The test `test_rename_with_custom_indexer_inplace` is part of the `Series` class in the `pandas.core.series` package. This class has a wide range of methods, some of which are covered by failing tests. Here are a few methods that are covered by failing tests that could potentially be related to the bug:

- `.__init__`
- `._set_axis`
- `._set_subtyp`
- `._update_inplace`
- `.name`
- `.dtype`
- `.values`
- `.get_values`
- `.name`
- `.reset_index`
- `.to_string`
- `.to_dict`
- `.to_frame`
- `.to_sparse`
- `._.set_name`
- `.rename`

Please let me know which method you would like to investigate further.
</details>
<hr>


<details>
  <summary><span style="font-size:20px;font-weight:gold;">Explanation 5 (4 lines, 0 code blocks)</span></summary>
  
  Based on the code snippet of the `rename` method in the `pandas.core.series.Series` class, we can see that the `rename` method accepts an `index` argument, which can be a scalar, hashable sequence, dictionary-like object, or a function. If the `index` argument is not a mapping object, the method calls the `_set_name` method to change the name of the series. Otherwise, it calls the `rename` method of the superclass `pandas.core.generic.NDFrame` with the `index` argument passed.

Since the error occurs when trying to convert the `ix` argument to a list, it suggests that the `ix` object passed to the `rename` method is not a mapping object. This is consistent with the fact that the error message states that the `'MyIndexer' object is not iterable`.

To resolve the error, the `ix` object should be a mapping object, such as a dictionary, that maps old index labels to new index labels. However, based on the provided test code, the `ix` object is an instance of the `MyIndexer` class, which does not implement the required mapping behavior.

To fix the issue, the `ix` object should be replaced with a dictionary-like object that provides the desired mapping.
</details>
<hr>

### GPT-4

<details>
  <summary><span style="font-size:20px;font-weight:gold;">Explanation 1 (7 lines, 2 code blocks)</span></summary>
  
  The test `test_rename_with_custom_indexer` in the file `pandas/tests/series/test_alter_axes.py` at line 276 failed with a `TypeError: 'MyIndexer' object is not iterable`.

This happens when the Series object `s` is created with a custom indexer `ix` of type `MyIndexer`: 

```python
s = Series([1, 2, 3]).rename(ix)
```

The `rename` method of the `Series` class expects either a scalar, a hashable sequence, dict-like or function for the parameter `index`. In this case, a non-iterable `MyIndexer` object is passed as an argument. 

The method seems to allow renaming with a mapping or function that modifies the labels, but it doesn't have an explicit check that the `index` argument is an iterable if it's not a scalar or not dict-like. This leads python to attempt to iterate over it, leading to the `TypeError: 'MyIndexer' object is not iterable` when `ensure_index` is invoked by `get_indexer_for` method.

Looking at the source code of the `Series.rename` method, it uses the following condition to classify non mapping indices:
```python
non_mapping = is_scalar(index) or (
    is_list_like(index) and not is_dict_like(index)
)
```
This condition allows the `MyIndexer` object to pass through, since it is not a scalar, not list-like and not dict-like. However, later on in the call to `get_indexer_for`, it fails as python tries to iterate over the `MyIndexer` object. 

To prevent such errors, a suitable check for the parameter should be added before it's used, and a descriptive error message should inform the user if the index is not of the proper type.
</details>
<hr>


<details>
  <summary><span style="font-size:20px;font-weight:gold;">Explanation 2 (6 lines, 2 code blocks)</span></summary>
  
  The failure is happening because the `rename` method of the `Series` class is being called with a non-iterable object as its index, as indicated by the error message from the call stack:

```
E           TypeError: 'MyIndexer' object is not iterable
>       s.rename(ix, inplace=True)
```

This object, an instance of the `MyIndexer` class, is not something that the `rename` method of `Series` knows how to handle.

Looking at the code for the `rename` method from the `Series` class, we see that the method expects either a scalar, a hashable sequence, a dict-like object, or a function for its `index` parameter - dict-like objects or functions are transformations to apply to the index, scalar or hashable sequence-like will alter the `Series.name` attribute. We see in the code:

```python
non_mapping = is_scalar(index) or (
    is_list_like(index) and not is_dict_like(index)
)
```

Here, the variable `non_mapping` refers to whether the input argument (`index`) is not a mapping (like a dictionary). If the `index` is a scalar (a single value) or is list-like (can be iterated over) but not dict-like, the index is set to be the `index` parameter. This cannot be done for `MyIndexer` object which is not iterable, and hence the TypeError is raised.

Hence, in the test case, by passing an instance of the `MyIndexer` class to the `rename` method of `Series`, we gave it an input that it did not know how to handle, because `MyIndexer` instances are not iterable, hence the observed error is thrown. 

The code in the test should be modified to handle this, the `index` passed in the test should be compatible with the operations performed in the `rename` method. This could be a scalar, a hashable sequence, a dict-like object, or a function.
</details>
<hr>


<details>
  <summary><span style="font-size:20px;font-weight:gold;">Explanation 3 (6 lines, 0 code blocks)</span></summary>
  
  The error arises from the `rename` function of the `pandas.core.series.Series` class. This class implements the main data structure in pandas, the Series. The 'rename' method is used to alter the index labels or the name of a Series.

From the failing test, we can see that a `MyIndexer` object is passed as an argument to the `rename` method. However, the `rename` method expects either a scalar, a hashable sequence, a function, or a dictionary-like argument. If the argument does not fit any of these categories, it is treated as a non-mapping argument. 

In this case, the `MyIndexer` is not a scalar, sequence, function, or any form of a dictionary-like object, and thus is considered an invalid argument. This is why the test `test_rename_with_custom_indexer` fails and raises the `TypeError: 'MyIndexer' object is not iterable` error.

To resolve this issue, one must ensure that the argument passed to the `rename` method is either a scalar, hashable sequence, function or dictionary-like. In the given test, the `rename` method should be modified to handle or reject invalid arguments appropriately. This will prevent a TypeError from being raised when non-iterable objects are passed as arguments. 

The failing test indicates weak error-handling and type-checking capabilities within the `rename` method of the `Series` class and suggests that this method's implementation should be revisited to better handle non-standard arguments.
pandas.core.series.Series.rename
</details>
<hr>


<details>
  <summary><span style="font-size:20px;font-weight:gold;">Explanation 4 (13 lines, 0 code blocks)</span></summary>
  
  The issue occurs during the `s.rename(ix, inplace=True)` operation, which is intended to rename the Series `s` with the indexes provided by `ix`. In this case, `ix` is an instance of the `MyIndexer` class which is not iterable.

This is causing the `rename` method in the `Series` class (`pandas.core.series.Series.rename`) to attempt to handle `ix` as a mapping (dict-like) for renaming. However, since `ix` is not iterable, this results in a `TypeError`.

More specifically:

1. `s.rename(ix, inplace=True)` calls `rename` in `pandas.core.series.Series`.

2. The method checks if `index` (`ix` in our case) is a `non_mapping`. Since `ix` is not iterable, it treats it like a dict-like sequence. 

3. This eventually leads to `ensure_index(index_like)` being called in `pandas.core.indexes.base.get_indexer` where `index_like` is `ix` (instance of `MyClass`).

4. In `ensure_index`, since `index_like` (i.e., `ix`) is not an instance of an `Index`, doesn't have a `name` attribute and is not a list or iterator, it tries to create an `Index` instance directly from it (`Index(index_like)`).

5. The `Index` constructor eventually calls `values = list(values)` where `values` is `ix`. This finally causes the `TypeError: 'MyIndexer' object is not iterable`, as the instance of `MyIndexer` is not iterable. 

The bug is essentially caused by the `rename` method treating `ix` as a mapping for renaming, which it is not. The `rename` method should be corrected to handle such cases where the `index` parameter does not correspond to a valid sequence or mapping for renaming, or at least provide clear error messaging. Alternatively, the definition and usage of the `MyIndexer` class within the test could also be adapted to suit the requirements of the `rename` method.
pandas.core.series.Series.rename
pandas.core.indexes.base.Index.get_indexer_for
pandas.core.indexes.base.Index.get_indexer
pandas.core.indexes.base.ensure_index
</details>
<hr>


<details>
  <summary><span style="font-size:20px;font-weight:gold;">Explanation 5 (5 lines, 0 code blocks)</span></summary>
  
  The `asarray_tuplesafe` function in `pandas.core.common` also tries to convert the input into a list at line 231. The condition at line 230 checks if the input is a list, tuple, or if it has an attribute `__array__`. If none of the conditions is true, the function tries to convert the input to a list, which again leads to a `TypeError` when the input is not iterable.

This function also lacks a mechanism to handle non-iterable inputs, leading to the issue presented in the failing test. As previously suggested, we should add an additional condition to check if the object is also iterable. If it is not, the function could raise an informative error or return a default value. 

The locations that need to be fixed are:

- `pandas.core.indexes.base.ensure_index`
- `pandas.core.common.asarray_tuplesafe`
</details>
<hr>

​

