# Explanation
### GPT-3.5

<details>
  <summary><span style="font-size:20px;font-weight:bold;">Explanation 1 (10 lines, 3 code blocks)</span></summary>
  
  <details>
    <summary>English (original)</summary>
  Title: Diagnosis of test `test_rename_with_custom_indexer`

Details: The test `test_rename_with_custom_indexer` is testing the `rename` method of the `Series` class in the `pandas.core.series` package. The test creates an instance of `Series` with values `[1, 2, 3]` and attempts to rename it using a custom indexer `MyIndexer`. However, the test fails with a `TypeError` indicating that the `MyIndexer` object is not iterable.

Looking at the code of the `Series.rename` method, we can see that it accepts an `index` parameter which can be a scalar, hashable sequence, dict-like, or function. In the test, an instance of `MyIndexer` is passed as the `index` argument. However, `MyIndexer` is not iterable, which results in the `TypeError` when trying to iterate over it.

To fix this issue, we need to ensure that the `index` argument passed to the `Series.rename` method is iterable. This can be done by either passing a valid iterable object such as a list or tuple, or by modifying the `MyIndexer` class to implement the necessary iterable interface.

Suggested fix:
- Modify the `test_rename_with_custom_indexer` test to pass a valid iterable object as the `index` argument.
- Update the `MyIndexer` class to implement the necessary iterable interface if it needs to be used as the `index` argument.

Code snippet of the failing test:
```python
    def test_rename_with_custom_indexer(self):
        # GH 27814
        class MyIndexer:
            pass

        ix = MyIndexer()
        s = Series([1, 2, 3]).rename(ix)
```

Suggested fix:
```python
    def test_rename_with_custom_indexer(self):
        # GH 27814
        ix = [1, 2, 3]
        s = Series([1, 2, 3]).rename(ix)
```
or
```python
    class MyIndexer:
        def __iter__(self):
            # implement the iterable interface
            yield 1
            yield 2
            yield 3

    ix = MyIndexer()
    s = Series([1, 2, 3]).rename(ix)
```

  </details>

  <details>
    <summary>Korean (translated)</summary>
제목: 테스트 `test_rename_with_custom_indexer` 분석

설명: 테스트 `test_rename_with_custom_indexer`는 `pandas.core.series` 패키지에 속한 `Series` 클래스의 `rename` 함수를 테스트하고 있습니다. 테스트는 값이 `[1, 2, 3]`인 `Series` 인스턴스를 생성하고 `MyIndexer`라는 커스텀 인덱서를 사용하여 이름을 바꾸려고 합니다. 하지만, 테스트는 `MyIndexer` 객체가 iterable하지 않다는 TypeError를 발생시킵니다.

`Series.rename` 함수의 코드를 보면 `index` 매개변수의 값으로 스칼라, 해시 가능한 시퀀스, dictionary와 같은 객체, 함수를 받을 수 있음이 드러납니다. 테스트에서 `MyIndexer`의 인스턴스가 `index` 인자로 전달됩니다. 그러나 `MyIndexer`는 iterable하지 않기 때문에 iterate하려고 할 때 `TypeError`가 발생합니다.

이 문제를 해결하려면 `Series.rename` 함수에 전달되는 `index` 인자가 iterable한지 확인해야 합니다. list나 tuple과 같은 유효한 반복 가능 객체를 전달하거나 `MyIndexer` 클래스를 수정하여 필요한 iteration 인터페이스를 구현하여 문제를 해결할 수 있습니다.

수정 방법 제안:
- `test_rename_with_custom_indexer` 테스트를 수정하여 `index` 인자로 유효한 iterable한 객체를 전달합니다.
- `MyIndexer` 클래스가 index 인자로 사용되어야 한다면, 필요한 iterable 인터페이스를 구현하여 업데이트합니다.

실패한 테스트 코드
```python
    def test_rename_with_custom_indexer(self):
        # GH 27814
        class MyIndexer:
            pass

        ix = MyIndexer()
        s = Series([1, 2, 3]).rename(ix)
```

제안된 수정 방법:
```python
    def test_rename_with_custom_indexer(self):
        # GH 27814
        ix = [1, 2, 3]
        s = Series([1, 2, 3]).rename(ix)
```
또는
```python
    class MyIndexer:
        def __iter__(self):
            # implement the iterable interface
            yield 1
            yield 2
            yield 3

    ix = MyIndexer()
    s = Series([1, 2, 3]).rename(ix)
```
  </details>
</details>
<hr>


<details>
  <summary><span style="font-size:20px;font-weight:bold;">Explanation 2 (17 lines, 3 code blocks)</span></summary>
  
  <details>
    <summary>English (original)</summary>
  The test `test_rename_with_custom_indexer_inplace` is calling the `rename` method of the `Series` class in the pandas core module. Here is the snippet of the `rename` method:

```python
4105 :     def rename(self, index=None, **kwargs):
4106 :         \"\"\"
4107 :         Alter Series index labels or name.
...
4171 :         if non_mapping:
4172 :             return self._set_name(index, inplace=kwargs.get(\"inplace\"))
4173 :         return super().rename(index=index, **kwargs)
```

Based on the error message and call stack, the error occurred at line 286 of the test, where `s.rename(ix, inplace=True)` is called. The error message indicates that a `TypeError` occurred during the execution of the `rename` method. It specifically states that the `'MyIndexer' object is not iterable`. 

To understand how this error occurred, we need to examine the `rename` method. The method checks whether the `index` parameter passed to it is a scalar or a non-mapping object (such as a list-like object that is not dict-like). If the `index` is a scalar or a non-mapping object, it calls the `_set_name` method with the `index` parameter and the `inplace` parameter passed to the `rename` method. Otherwise, it calls the `rename` method of the super class.

Since the error message mentions that the `'MyIndexer' object is not iterable`, it implies that the `index` parameter supplied to the `rename` method is not a scalar or a non-mapping object. This indicates that the `ix` object of the `MyIndexer` class is causing the error. The `MyIndexer` class is defined within the `test_rename_with_custom_indexer_inplace` test method.

To resolve this error, the `MyIndexer` class should either implement the required methods to be considered a valid indexer for the `rename` method, or a valid index-like object should be used as the `index` parameter when calling the `rename` method.

To fix the issue, you can modify the test to use a valid index-like object instead of the `MyIndexer` class, or modify the `MyIndexer` class to provide the required methods for it to be considered a valid indexer by the `rename` method.

Here is the suggested fix:

```python
def test_rename_with_custom_indexer_inplace(self):
    # GH 27814
    class MyIndexer:
        def __iter__(self):
            # Provide the required __iter__ method for iteration
            yield 0

    ix = MyIndexer()
    s = Series([1, 2, 3])
    s.rename(ix, inplace=True)
```

This modified `MyIndexer` class includes the `__iter__` method, which allows it to be considered an iterable object.

Alternatively, you can use a valid index-like object instead of the `MyIndexer` class:

```python
def test_rename_with_custom_indexer_inplace(self):
    # GH 27814
    ix = pd.Index([0])
    s = Series([1, 2, 3])
    s.rename(ix, inplace=True)
```

In this case, the `pd.Index` class is used to create a valid index-like object.

Note: The exact fix depends on the requirements and intentions of the test code.

Suggested fix:

pandas.core.series.Series.rename(Any, inplace=bool)
Title: Diagnosis of test `test_rename_with_custom_indexer_inplace`
Details: The test `test_rename_with_custom_indexer_inplace` is failing with a `TypeError` indicating that the `'MyIndexer' object is not iterable`. The error occurs at line 286 of the test, where the `rename` method of the `Series` class is called. The `rename` method checks whether the `index` parameter is a scalar or a non-mapping object. If it is, it calls the `_set_name` method with the `index` parameter. Otherwise, it calls the `rename` method of the super class. Since the error message points to the `'MyIndexer' object is not iterable`, it suggests that the `MyIndexer` class used as the `index` parameter is causing the error. To fix this, the `MyIndexer` class should implement the required methods to be considered a valid indexer for the `rename` method, or a valid index-like object should be used instead.

Suggested fix:
pandas.core.series.Series.rename(Any, inplace=bool)
  </details>
  <details>
    <summary>Korean (translated)</summary>

`test_rename_with_custom_indexer_inplace` 테스트는 pandas core 모듈에 속한 `Series` 클래스의 `rename` 함수를 호출하고 있습니다. `rename` 함수의 코드는 다음과 같습니다:

```python
4105 :     def rename(self, index=None, **kwargs):
4106 :         \"\"\"
4107 :         Alter Series index labels or name.
...
4171 :         if non_mapping:
4172 :             return self._set_name(index, inplace=kwargs.get(\"inplace\"))
4173 :         return super().rename(index=index, **kwargs)
```

에러메시지와 call stack을 기반으로, 에러는 테스트의 `s.rename(ix, inplace=True)`행이 호출되는 테스트의 286행에서 발생한 것으로 보입니다. 에러메시지는 `rename` 함수 실행 중 `TypeError`가 발생했음을 나타냅니다. 구체적으로 `'MyIndexer' object is not iterable` 이라고 명시되어 있습니다.

이 오류가 어떻게 발생했는지 이해하려면 `rename` 함수를 살펴보아야 합니다. 이 함수는 전달된 `index` 파라미터가 스칼라나 매핑하지 않는 객체(딕셔너리와 같지 않으면서 리스트와 같은 객체)인지 확인합니다. `index`가 스칼라나 매핑하지 않는 객체이면 `rename` 함수에 전달된 `index`와 `inplace` 파라미터로 `_set_name` 함수를 호출합니다. 그렇지 않으면 super class의 `rename` 함수를 호출합니다.

오류 메시지가 `'MyIndexer' object is not iterable` 라고 언급하고 있는데, 이는 `rename` 함수에 전달된 `index` 파라미터가 스칼라나 매핑되지 않은 객체가 아닌 것을 시사합니다. 따라서 `MyIndexer` 클래스의 `ix` 객체가 오류의 원인인 것으로 보입니다. `MyIndexer` 클래스는 `test_rename_with_custom_indexer_inplace` 테스트 함수 내에서 정의되어 있습니다. 

이 문제를 해결하기 위해서는 `MyIndexer` 클래스가 `rename` 함수에 대한 유효한 인덱서로 간주되기 위해 필요한 함수들을 구현하거나, `rename` 메소드를 호출할 때 index 매개변수로 유효한 index-like 객체를 사용해야 합니다.

문제를 해결하기 위해 테스트에서 `MyIndexer` 클래스 대신 유효한 index-like 객체를 사용하거나, `MyIndexer` 클래스를 수정하여 `rename` 메소드에 의해 유효한 indexer로 간주되기 위해 필요한 메소드들을 제공하도록 할 수 있습니다. 

아래는 제시된 fix입니다:

```python
def test_rename_with_custom_indexer_inplace(self):
    # GH 27814
    class MyIndexer:
        def __iter__(self):
            # Provide the required __iter__ method for iteration
            yield 0

    ix = MyIndexer()
    s = Series([1, 2, 3])
    s.rename(ix, inplace=True)
```

수정된 `MyIndexer` 클래스에 `__iter__` 메소드가 추가되어, iterable 객체로 간주될 수 있게 되었습니다.

혹은 `MyIndexer` 클래스 대신 유효한 index-like 객체를 사용하는 것도 방법이 될 수 있습니다:

```python
def test_rename_with_custom_indexer_inplace(self):
    # GH 27814
    ix = pd.Index([0])
    s = Series([1, 2, 3])
    s.rename(ix, inplace=True)
```

이 경우에는, 유효한 index-like object를 만들기 위해 `pd.Index` 클래스가 사용되었습니다.

정확한 수정은 requirement와 테스트 코드의 의도에 달려있다는 것을 주의해주세요.

수정 제안:

pandas.core.series.Series.rename(Any, inplace=bool)

제목: `test_rename_with_custom_indexer_inplace` 테스트 분석

상세: `test_rename_with_custom_indexer_inplace` 테스트는 `'MyIndexer' object is not iterable`라는 오류 메시지와 함께 실패합니다. 이 오류는 `Series` 클래스의 `rename` 함수가 호출되는 테스트의 286행에서 발생합니다. `rename` 함수는 `index` 매개변수가 스칼라 또는 비매핑 개체인지 확인합니다. 만약 그렇다면, `index` 매개변수와 함께 `_set_name` 함수를 호출합니다. 그렇지 않으면, 상위 클래스의 `rename` 함수를 호출합니다. 오류 메시지가 `'MyIndexer' object is not iterable`를 가리키고 있으므로, `index` 매개변수로 사용된 `MyIndexer` 클래스가 오류를 발생시키고 있음을 알 수 있습니다. 이를 해결하려면 `MyIndexer` 클래스는 `rename` 함수에 대한 유효한 indexer 또는 유효한 index-like 객체로 간주되기 위해 필요한 함수를 구현해야 합니다.

수정 제안:
pandas.core.series.Series.rename(Any, inplace=bool)

  </details>
</details>
<hr>


<details>
  <summary><span style="font-size:20px;font-weight:bold;">Explanation 3 (4 lines, 0 code blocks)</span></summary>
    <details>
      <summary>English (original)</summary>

  The failing test `['pandas.tests.series.test_alter_axes.TestSeriesAlterAxes.test_rename_with_custom_indexer()']` covers classes from various packages in the pandas library, including `pandas.core.series`, `pandas.core.generic`, `pandas.core.indexes.base`, and `pandas.core.common`.
The test `test_rename_with_custom_indexer` failed with a `TypeError` when calling the `rename()` method on a `Series` object. The error message indicates that the `'MyIndexer'` object is not iterable.

Based on the given code snippet, the `rename()` method is called on a `Series` object with the argument `ix`, which is an instance of the `MyIndexer` class. The error occurs when the method tries to convert the `ix` argument to a list using the `list()` function. This conversion fails because the `MyIndexer` class does not implement the iterable protocol.

To further investigate the issue, let's retrieve the code snippet for the `rename()` method in the `Series` class.

  </details>
  

  <details>
    <summary>Korean (Translated)</summary>

실패한 테스트 `['pandas.tests.series.test_alter_axes.TestSeriesAlterAxes.test_rename_with_custom_indexer()']`는 `pandas.core.series`, `pandas.core.generic`, `pandas.core.indexes.base`, 및 `pandas.core.common` 등 pandas 라이브러리의 다양한 패키지를 커버합니다.

`test_rename_with_custom_indexer` 테스트는 `Series` 객체의 `rename()` 함수를 호출할 때 `TypeError`로 실패했습니다. 오류 메시지는 `'MyIndexer'` 객체가 iterable하지 않다는 것을 나타냅니다.

제공된 코드에 따르면, `rename()` 함수는 `MyIndexer` 클래스의 인스턴스인 `ix` 인수와 함께 `Series` 객체에서 호출됩니다. 오류는 `list()` 함수를 사용하여 `ix` 인수를 리스트로 변환하려고 할 때 발생합니다. 이 변환은 `MyIndexer` 클래스가 iterable 프로토콜을 구현하지 않기 때문에 실패합니다.

문제를 더 조사하기 위해, `Series` 클래스의 `rename()` 함수에 대한 코드 스니펫을 찾아보겠습니다.

  </details>
</details>
<hr>


<details>
  <summary><span style="font-size:20px;font-weight:bold;">Explanation 4 (18 lines, 0 code blocks)</span></summary>
  
  <details>
  <summary>English (original)</summary>
  The test `test_rename_with_custom_indexer_inplace` is part of the `Series` class in the `pandas.core.series` package. This class has a wide range of methods, some of which are covered by failing tests. Here are a few methods that are covered by failing tests that could potentially be related to the bug:

- `.__init__`
- `._set_axis`
- `._set_subtyp`
- `._update_inplace`
- `.name`
- `.dtype`
- `.values`
- `.get_values`
- `.name`
- `.reset_index`
- `.to_string`
- `.to_dict`
- `.to_frame`
- `.to_sparse`
- `._.set_name`
- `.rename`

Please let me know which method you would like to investigate further.
</details>
<details>
  <summary>Korean (translated)</summary>
  `test_rename_with_custom_indexer_inplace` 테스트는 `pandas.core.series` 패키지의 `Series` 클래스의 일부입니다. 이 클래스는 다양한 함수를 가지고 있으며, 일부는 실패한 테스트에 의해 커버됩니다. 다음은 버그와 관련될 수 있는 실패한 테스트에 의해 커버되는 몇 가지 함수입니다.

- `.__init__`
- `._set_axis`
- `._set_subtyp`
- `._update_inplace`
- `.name`
- `.dtype`
- `.values`
- `.get_values`
- `.name`
- `.reset_index`
- `.to_string`
- `.to_dict`
- `.to_frame`
- `.to_sparse`
- `._.set_name`
- `.rename`

추가로 조사하고자 하는 함수를 알려주세요.
</details>
</details>
<hr>


<details>
  <summary><span style="font-size:20px;font-weight:bold;">Explanation 5 (4 lines, 0 code blocks)</span></summary>
  
  <details>
    <summary>English (original)</summary>
  Based on the code snippet of the `rename` method in the `pandas.core.series.Series` class, we can see that the `rename` method accepts an `index` argument, which can be a scalar, hashable sequence, dictionary-like object, or a function. If the `index` argument is not a mapping object, the method calls the `_set_name` method to change the name of the series. Otherwise, it calls the `rename` method of the superclass `pandas.core.generic.NDFrame` with the `index` argument passed.

Since the error occurs when trying to convert the `ix` argument to a list, it suggests that the `ix` object passed to the `rename` method is not a mapping object. This is consistent with the fact that the error message states that the `'MyIndexer' object is not iterable`.

To resolve the error, the `ix` object should be a mapping object, such as a dictionary, that maps old index labels to new index labels. However, based on the provided test code, the `ix` object is an instance of the `MyIndexer` class, which does not implement the required mapping behavior.

To fix the issue, the `ix` object should be replaced with a dictionary-like object that provides the desired mapping.
</details>
<details>
  <summary>Korean (translated)</summary>
`pandas.core.series.Series` 클래스의 `rename` 메서드의 코드를 기반으로, `rename` 메서드는 스칼라, 해시 가능한 시퀀스, dictionary-like 객체 또는 함수일 수 있는 `index` 인수를 받음을 알 수 있습니다. `index` 인수가 mapping 객체가 아니면, 메서드는 시리즈의 이름을 변경하기 위해 `_set_name` 함수를 호출합니다. 그렇지 않으면, `pandas.core.generic.NDFrame` 상위 클래스의 `rename` 메서드를 `index` 인수와 함께 호출합니다.

오류가 `ix` 인수를 리스트로 변환하려고 할 때 발생하므로, `rename` 메서드에 전달된 `ix` 객체가 매핑 객체가 아니라는 것을 시사합니다. 이는 오류 메시지가 `'MyIndexer' object is not iterable`라고 명시하는 것과 일치합니다.

오류를 해결하려면, `ix` 객체는 오래된 인덱스 라벨을 새 인덱스 라벨로 매핑하는 dictionary와 같은 매핑 객체여야 합니다. 그러나 제공된 테스트 코드에 따르면, `ix` 객체는 필요한 매핑 동작을 구현하지 않는 `MyIndexer` 클래스의 인스턴스입니다.

문제를 해결하려면, 원하는 매핑을 제공하는 dictionary-like 객체로 `ix` 객체를 대체해야 합니다.
</details>
</details>
<hr>

### GPT-4

<details>
  <summary><span style="font-size:20px;font-weight:bold;">Explanation 1 (7 lines, 2 code blocks)</span></summary>
  
  <details>
    <summary>English (original)</summary>
  The test `test_rename_with_custom_indexer` in the file `pandas/tests/series/test_alter_axes.py` at line 276 failed with a `TypeError: 'MyIndexer' object is not iterable`.

This happens when the Series object `s` is created with a custom indexer `ix` of type `MyIndexer`: 

```python
s = Series([1, 2, 3]).rename(ix)
```

The `rename` method of the `Series` class expects either a scalar, a hashable sequence, dict-like or function for the parameter `index`. In this case, a non-iterable `MyIndexer` object is passed as an argument. 

The method seems to allow renaming with a mapping or function that modifies the labels, but it doesn't have an explicit check that the `index` argument is an iterable if it's not a scalar or not dict-like. This leads python to attempt to iterate over it, leading to the `TypeError: 'MyIndexer' object is not iterable` when `ensure_index` is invoked by `get_indexer_for` method.

Looking at the source code of the `Series.rename` method, it uses the following condition to classify non mapping indices:
```python
non_mapping = is_scalar(index) or (
    is_list_like(index) and not is_dict_like(index)
)
```
This condition allows the `MyIndexer` object to pass through, since it is not a scalar, not list-like and not dict-like. However, later on in the call to `get_indexer_for`, it fails as python tries to iterate over the `MyIndexer` object. 

To prevent such errors, a suitable check for the parameter should be added before it's used, and a descriptive error message should inform the user if the index is not of the proper type.
</details>
<details>
  <summary>Korean (translated)</summary>
`pandas/tests/series/test_alter_axes.py` 파일의 `test_rename_with_custom_indexer` 테스트는 276행에서 `TypeError: 'MyIndexer' object is not iterable` 에러로 실패했습니다.

이는 `Series` 객체 `s`가 `MyIndexer` 유형의 사용자 지정 indexer `ix`를 인자로 생성될 때 발생합니다:

```python
s = Series([1, 2, 3]).rename(ix)
```

`Series` 클래스의 `rename` 함수는 `index` 매개변수로 스칼라, 해시 가능한 시퀀스, dictionary-like 객체 또는 함수를 받습니다. 이 경우, iterable하지 않은 `MyIndexer` 객체가 인수로 전달됩니다.

함수는 라벨을 수정하는 매핑 또는 함수를 사용하여 이름을 변경할 수 있도록 허용하는 것처럼 보이지만, `index` 인수가 스칼라 또는 dictionary-like가 아닌 경우 iterable한지 확인하는 명시적인 검사가 없습니다. 이로 인해 python이 iteration하려고 시도하면 `TypeError: 'MyIndexer' object is not iterable`가 발생합니다.

`Series.rename` 메서드의 코드를 살펴보면, 다음과 같은 조건을 사용하여 매핑 인덱스를 분류합니다:

```python
non_mapping = is_scalar(index) or (
    is_list_like(index) and not is_dict_like(index)
)
```

이 조건은 `MyIndexer` 객체가 스칼라, list-like 및 dict-like가 아니므로 통과할 수 있도록 허용합니다. 그러나 이후 `get_indexer_for` 호출에서 python이 `MyIndexer` 객체를 iterate하려고 시도하므로 실패합니다.

이러한 오류를 방지하기 위해, 매개변수를 사용하기 전에 적절한 검사를 추가하고, 적절한 오류 메시지를 사용하여 인덱스가 적절한 유형이 아닌 경우 사용자에게 알려야 합니다.
</details>
</details>
<hr>


<details>
  <summary><span style="font-size:20px;font-weight:bold;">Explanation 2 (6 lines, 2 code blocks)</span></summary>
  
  <details>
    <summary>English (original)</summary>
  The failure is happening because the `rename` method of the `Series` class is being called with a non-iterable object as its index, as indicated by the error message from the call stack:

```
E           TypeError: 'MyIndexer' object is not iterable
>       s.rename(ix, inplace=True)
```

This object, an instance of the `MyIndexer` class, is not something that the `rename` method of `Series` knows how to handle.

Looking at the code for the `rename` method from the `Series` class, we see that the method expects either a scalar, a hashable sequence, a dict-like object, or a function for its `index` parameter - dict-like objects or functions are transformations to apply to the index, scalar or hashable sequence-like will alter the `Series.name` attribute. We see in the code:

```python
non_mapping = is_scalar(index) or (
    is_list_like(index) and not is_dict_like(index)
)
```

Here, the variable `non_mapping` refers to whether the input argument (`index`) is not a mapping (like a dictionary). If the `index` is a scalar (a single value) or is list-like (can be iterated over) but not dict-like, the index is set to be the `index` parameter. This cannot be done for `MyIndexer` object which is not iterable, and hence the TypeError is raised.

Hence, in the test case, by passing an instance of the `MyIndexer` class to the `rename` method of `Series`, we gave it an input that it did not know how to handle, because `MyIndexer` instances are not iterable, hence the observed error is thrown. 

The code in the test should be modified to handle this, the `index` passed in the test should be compatible with the operations performed in the `rename` method. This could be a scalar, a hashable sequence, a dict-like object, or a function.
</details>
<details>
  <summary>Korean (translated)</summary>
이 실패가 발생하는 이유는 호출 스택의 오류 메시지에서 확인할 수 있듯이 `Series` 클래스의 `rename` 함수가 `non-iterable` 객체가 아닌 인덱스와 함께 호출되기 때문입니다:

```
E           TypeError: 'MyIndexer' object is not iterable
>       s.rename(ix, inplace=True)
```

이 객체는 Series의 `rename` 함수가 어떻게 처리할 지 모르는 `MyIndexer` 클래스의 인스턴스입니다. `Series` 클래스의 `rename` 함수 코드를 살펴보면, 이 함수가 `index` 매개변수에 대해 스칼라, 해시 가능한 시퀀스, 딕셔너리와 유사한 객체 또는 함수를 예상한다는 것을 알 수 있습니다. 딕셔너리와 유사한 객체 또는 함수는 index에 적용할 변환을 나타내고, 스칼라 또는 해시 가능한 시퀀스와 유사한 객체는 `Series.name` 속성을 변경합니다. 이는 다음 코드에서 확인할 수 있습니다:

```python
non_mapping = is_scalar(index) or (
    is_list_like(index) and not is_dict_like(index)
)
```

여기서 `non_mapping` 변수는 입력 인자 (`index`)가 dictionary와 같은 mapping이 아님을 나타냅니다. 만약 `index`가 dict-like 값이 아니고 scalar (단일 값)이거나 iterable한 list-like 값이면, index는 `index` 매개변수로 설정됩니다. `MyIndexer` 객체는 iteralbe 하지 않기 때문에 이렇게 될 수 없고, 따라서 TypeError가 발생합니다. 따라서 이 테스트 케이스는 Series의 `rename` 함수에 반복 가능한 객체가 아닌 `MyIndexer` 클래스의 인스턴스를 전달함으로써, 처리할 수 없는 입력을 제공하였고 관찰된 에러가 발생하였습니다. 

테스트의 코드를 수정하여 `rename` 함수에서 수행되는 작업과 호환되는 `index`를 전달해야 합니다. 이는 스칼라, 해시 가능한 시퀀스, 딕셔너리와 유사한 객체 또는 함수일 수 있습니다.
</details>
</details>
<hr>


<details>
  <summary><span style="font-size:20px;font-weight:bold;">Explanation 3 (6 lines, 0 code blocks)</span></summary>
  
  <details>
    <summary>English (original)</summary>
  The error arises from the `rename` function of the `pandas.core.series.Series` class. This class implements the main data structure in pandas, the Series. The 'rename' method is used to alter the index labels or the name of a Series.

From the failing test, we can see that a `MyIndexer` object is passed as an argument to the `rename` method. However, the `rename` method expects either a scalar, a hashable sequence, a function, or a dictionary-like argument. If the argument does not fit any of these categories, it is treated as a non-mapping argument. 

In this case, the `MyIndexer` is not a scalar, sequence, function, or any form of a dictionary-like object, and thus is considered an invalid argument. This is why the test `test_rename_with_custom_indexer` fails and raises the `TypeError: 'MyIndexer' object is not iterable` error.

To resolve this issue, one must ensure that the argument passed to the `rename` method is either a scalar, hashable sequence, function or dictionary-like. In the given test, the `rename` method should be modified to handle or reject invalid arguments appropriately. This will prevent a TypeError from being raised when non-iterable objects are passed as arguments. 

The failing test indicates weak error-handling and type-checking capabilities within the `rename` method of the `Series` class and suggests that this method's implementation should be revisited to better handle non-standard arguments.
pandas.core.series.Series.rename
</details>
<details>
  <summary>Korean (translated)</summary>
이 오류는 `pandas.core.series.Series` 클래스의 `rename` 함수에서 발생합니다. 이 클래스는 pandas의 주요 데이터 구조인 Series를 구현하고 있으며, 'rename' 함수는 Series의 index 레이블이나 이름을 변경하는 데 사용됩니다.

실패한 테스트를 통해 `MyIndexer` 객체가 `rename` 함수에 인수로 전달되었다는 것을 알 수 있습니다. 그러나 `rename` 함수는 스칼라, 해시 가능한 시퀀스, 함수 또는 딕셔너리와 유사한 인수 중 하나를 예상합니다. 인수가 이러한 범주에 들어맞지 않는 경우, 매핑되지 않는 (non-mapping) 인수로 처리됩니다.

이 경우 `MyIndexer`는 스칼라, 시퀀스, 함수 또는 딕셔너리와 유사한 객체가 아니며, 따라서 유효하지 않은 인수로 간주됩니다. 

이는 `test_rename_with_custom_indexer`가 실패하고 `TypeError: 'MyIndexer' object is not iterable` 에러가 발생하는 이유입니다.

이 문제를 해결하려면 `rename` 함수에 전달되는 인수가 스칼라, 해시 가능한 시퀀스, 함수 또는 딕셔너리와 유사한 객체인지 확인해야 합니다. 주어진 테스트에서는 `rename` 함수를 수정하여 유효하지 않은 인수를 적절하게 처리하거나 거부해야 합니다. 이렇게 하면 non-iterable한 객체가 인수로 전달될 때 TypeError가 발생하는 것을 방지할 수 있습니다.

이 실패한 테스트는 `Series` 클래스의 `rename` 함수의 오류 처리 및 타입 체킹이 부족하다는 것을 나타내며, 이 함수의 구현을 검토하여 비 표준 인수를 더 잘 처리하도록 개선해야 함을 시사합니다.

pandas.core.series.Series.rename
</details>
</details>
<hr>


<details>
  <summary><span style="font-size:20px;font-weight:bold;">Explanation 4 (13 lines, 0 code blocks)</span></summary>
  
  <details>
    <summary>English (original)</summary>
  The issue occurs during the `s.rename(ix, inplace=True)` operation, which is intended to rename the Series `s` with the indexes provided by `ix`. In this case, `ix` is an instance of the `MyIndexer` class which is not iterable.

This is causing the `rename` method in the `Series` class (`pandas.core.series.Series.rename`) to attempt to handle `ix` as a mapping (dict-like) for renaming. However, since `ix` is not iterable, this results in a `TypeError`.

More specifically:

1. `s.rename(ix, inplace=True)` calls `rename` in `pandas.core.series.Series`.

2. The method checks if `index` (`ix` in our case) is a `non_mapping`. Since `ix` is not iterable, it treats it like a dict-like sequence. 

3. This eventually leads to `ensure_index(index_like)` being called in `pandas.core.indexes.base.get_indexer` where `index_like` is `ix` (instance of `MyClass`).

4. In `ensure_index`, since `index_like` (i.e., `ix`) is not an instance of an `Index`, doesn't have a `name` attribute and is not a list or iterator, it tries to create an `Index` instance directly from it (`Index(index_like)`).

5. The `Index` constructor eventually calls `values = list(values)` where `values` is `ix`. This finally causes the `TypeError: 'MyIndexer' object is not iterable`, as the instance of `MyIndexer` is not iterable. 

The bug is essentially caused by the `rename` method treating `ix` as a mapping for renaming, which it is not. The `rename` method should be corrected to handle such cases where the `index` parameter does not correspond to a valid sequence or mapping for renaming, or at least provide clear error messaging. Alternatively, the definition and usage of the `MyIndexer` class within the test could also be adapted to suit the requirements of the `rename` method.

pandas.core.series.Series.rename
pandas.core.indexes.base.Index.get_indexer_for
pandas.core.indexes.base.Index.get_indexer
pandas.core.indexes.base.ensure_index
</details>
<details>
  <summary>Korean (translated)</summary>
    이 문제는 Series `s`를 `ix`에서 제공한 인덱스로 이름을 변경하기 위한 `s.rename(ix, inplace=True)` 작업 중에 발생합니다. 여기서 `ix`는 non-iterable한 MyIndexer 클래스의 인스턴스입니다.

이로 인해 `Series` 클래스 내부의 `rename` 함수 (`pandas.core.series.Series.rename`)는 `ix`를 이름을 바꾸기 위한 mapping (dict-like)로 처리하려고 시도합니다. 하지만 `ix`는 iterable하지 않으므로 이는 `TypeError`를 발생시킵니다.

더 구체적으로:

1. `s.rename(ix, inplace=True)`은 `pandas.core.series.Series`의 `rename`을 호출합니다.
2. 함수는 `index` (이 경우는 `ix`)가 `non_mapping`인지 확인합니다. `ix` 는 non-iterable하므로 dict-like sequence로 처리됩니다.
3. 이것은 `pandas.core.indexes.base.get_indexer`의 `ensure_index(index_like)`를 호출하며, 여기서 `index_like` 는 `MyClass`의 인스턴스인 `ix`입니다.
4. `ensure_index` 함수는 `index_like` (즉, `ix`)가 `Index`의 인스턴스가 아니며 `name` 속성이 없으며 리스트 또는 iteratore 아니기 때문에 직접 `Index(index_like)`로부터 `Index` 인스턴스를 만들려고 시도합니다.
5. `Index` 생성자는 따라서 `values = list(values)`를 호출하며 (여기서 `values`는 `ix`), `MyIndexer`의 인스턴스가 iterable 하지 않기 때문에 여기서 최종적으로 `TypeError: 'MyIndexer' object is not iterable`이 발생합니다. 

이 버그는 본질적으로 `rename` 함수가 이름을 바꾸기 위한 매핑이 아닌 `ix`를 매핑으로 처리하여 발생합니다. `rename` 함수는 `index` 매개변수가 이름을 바꾸기 위한 유효한 시퀀스 또는 매핑에 해당하지 않는 경우를 처리할 수 있도록 바뀌거나, 적어도 명확한 오류 메시지를 제공하도록 수정되어야 합니다. 혹은, 테스트 내에서 `MyIndexer` 클래스의 정의 및 사용이 `rename` 함수의 요구 사항을 충족하도록 조정될 수 있습니다.

pandas.core.series.Series.rename
pandas.core.indexes.base.Index.get_indexer_for
pandas.core.indexes.base.Index.get_indexer
pandas.core.indexes.base.ensure_index
</details>
</details>
<hr>


<details>
  <summary><span style="font-size:20px;font-weight:bold;">Explanation 5 (5 lines, 0 code blocks)</span></summary>

<details>
  <summary>English (original)</summary>
  The `asarray_tuplesafe` function in `pandas.core.common` also tries to convert the input into a list at line 231. The condition at line 230 checks if the input is a list, tuple, or if it has an attribute `__array__`. If none of the conditions is true, the function tries to convert the input to a list, which again leads to a `TypeError` when the input is not iterable.

This function also lacks a mechanism to handle non-iterable inputs, leading to the issue presented in the failing test. As previously suggested, we should add an additional condition to check if the object is also iterable. If it is not, the function could raise an informative error or return a default value. 

The locations that need to be fixed are:

- `pandas.core.indexes.base.ensure_index`
- `pandas.core.common.asarray_tuplesafe`
</details>
<details>
  <summary>Korean (translated</summary>

`pandas.core.common`의 `asarray_tuplesafe` 함수도 231줄에서 입력을 리스트로 변환하려고 시도합니다. 230줄에 있는 조건문은 입력이 리스트, 튜플이거나 또는 `__array__` 속성을 가지고 있는지 확인합니다. 이러한 조건 중 어느 하나도 참이 아닌 경우 함수는 입력을 리스트로 변환하려고 하며, 입력이 iterable하지 않을 때 TypeError가 발생합니다.

이 함수도 non-iterable한 입력을 처리할 메커니즘을 가지고 있지 않으며, 실패하는 테스트에서 발생한 문제를 야기합니다. 이전에 제안한 대로 추가 조건을 추가하여 객체가 iterable한지 확인해야 합니다. 그렇지 않은 경우 이 함수는 정보 오류를 발생시키거나 기본값을 반환할 수 있습니다.

수정해야 할 위치는 다음과 같습니다:
- `pandas.core.indexes.base.ensure_index`
- `pandas.core.common.asarray_tuplesafe`
</details>

</details>
<hr>

​

